Workbook

Sheet ResearchAndDevCost
A1: Airqoon - R&D Cost
B3: Cost Item | C3: allocated resources in man/day | D3: component cost | E3: number of units | F3: total cost
A4: Core Hardware | B4: PCB Designer Wage + Overhead | C4: 2 | D4: 0 | E4: 0 | F4: =C4*$I$5+D4*E4 -> 1120 | I4: Inovatink man/day | L4: SW Dev man/day
B5: Tests | C5: 1 | D5: 0 | E5: 0 | F5: =C5*$I$5+D5*E5 -> 560 | I5: =8*70 -> 560 | L5: =20*8 -> 160
B6: Prototyping -> BOM + PCB + Integration | C6: 2 | D6: 0 | E6: 5 | F6: =C6*$I$5+D6*E6 -> 1120
B7: Technical Documentation | C7: 1 | D7: 0 | E7: 0 | F7: =C7*$I$5+D7*E7 -> 560
B8: PCB (HW) | C8: 1 | D8: 0 | E8: 0 | F8: =C8*$I$5+D8*E8 -> 560
B9: BOM - Components | C9: 1 | D9: 0 | E9: 0 | F9: =C9*$I$5+D9*E9 -> 560
B10: Logistics, Operational Overhead | C10: 0.5 | D10: 0 | E10: 0 | F10: =C10*$I$5+D10*E10 -> 280
E11: Total: | F11: =SUM(F4:F10) -> 4760
B14: Cost Item | C14: allocated resources in man/day | D14: component cost | E14: number of units | F14: total cost
A15: Peripheral Hardware | B15: PCB Designer Wage + Overhead | C15: 0.25 | D15: 0 | E15: 0 | F15: =C15*$I$5+D15*E15 -> 140
B16: Tests | C16: 1 | D16: 0 | E16: 0 | F16: =C16*$I$5+D16*E16 -> 560
B17: PoC (Evaluation Modules) | C17: 0 | D17: 0 | E17: 2 | F17: =C17*$I$5+D17*E17 -> 0
B18: Prototyping -> BOM + PCB + Integration | C18: 1 | D18: 0 | E18: 5 | F18: =C18*$I$5+D18*E18 -> 560
B19: Technical Documentation | C19: 1 | D19: 0 | E19: 0 | F19: =C19*$I$5+D19*E19 -> 560
B20: PCB (HW) | C20: 0.25 | D20: 0 | E20: 0 | F20: =C20*$I$5+D20*E20 -> 140
B21: BOM - Components | C21: 0 | D21: 0 | E21: 0 | F21: =C21*$I$5+D21*E21 -> 0
B22: Logistics, Operational Overhead | C22: 0.5 | D22: 0 | E22: 0 | F22: =C22*$I$5+D22*E22 -> 280
E23: Total: | F23: =SUM(F15:F22) -> 2240
B26: Cost Item | C26: allocated resources in man/day | D26: component cost | E26: number of units | F26: total cost
A27: Smart City Sense | B27: PCB Designer Wage + Overhead | C27: 0.25 | D27: 0 | E27: 0 | F27: =C27*$I$5+D27*E27 -> 140
B28: Tests | C28: 2 | D28: 0 | E28: 0 | F28: =C28*$I$5+D28*E28 -> 1120
B29: PoC (Evaluation Modules) | C29: 0 | D29: 0 | E29: 2 | F29: =C29*$I$5+D29*E29 -> 0
B30: Prototyping -> BOM + PCB + Integration | C30: 0.5 | D30: 0 | E30: 0 | F30: =C30*$I$5+D30*E30 -> 280
B31: Technical Documentation | C31: 1 | D31: 0 | E31: 0 | F31: =C31*$I$5+D31*E31 -> 560
B32: PCB (HW) | C32: 0.25 | D32: 0 | E32: 0 | F32: =C32*$I$5+D32*E32 -> 140
B33: BOM - Components | C33: 0 | D33: 0 | E33: 0 | F33: =C33*$I$5+D33*E33 -> 0
B34: Logistics, Operational Overhead | C34: 1 | D34: 0 | E34: 0 | F34: =C34*$I$5+D34*E34 -> 560
E35: Total: | F35: =SUM(F27:F34) -> 2800
E36: subtotal (HW): | F36: =SUM(F35,F23,F11) -> 9800
B39: Cost Item | C39: allocated resources in man/day | D39: component cost | E39: number of units | F39: total cost
A40: Software | B40: Software Developer Wage + Overhead | C40: 3 | D40: 0 | E40: 0 | F40: =C40*$I$5 -> 1680
B41: Tests | C41: 2 | D41: 0 | E41: 0 | F41: =C41*$I$5 -> 1120
B42: Technical Documentation | C42: 1 | D42: 0 | E42: 0 | F42: =C42*$I$5 -> 560
B43: Logistics, Operational Overhead | C43: 1 | D43: 0 | E43: 0 | F43: =C43*$I$5 -> 560
E44: Total: | F44: =SUM(F40:F43) -> 3920
E45: Overall: | F45: =SUM(F11,F23,F35,F44) -> 13720

Sheet BOMCost
A1: Airqoon BOM Cost
B2: Assembly Name : | C2: Airqoon | F2: [42]
B3: Assembly Number : | C3: 1
B4: Assembly Revision : | C4: 1
I6: 1 -> 1k (%) | J6: 1k -> 10k (%) | K6: 10k -> 20k (%)
I7: 0.75 | J7: 0.75 | K7: 0.8
A8: Pt # | B8: Part Name | C8: DigiKey Pt. No. | D8: Board | E8: Qty | F8: Supplier Web | G8: Unit Cost | H8: Unit Cost 100 | I8: Unit Cost(1k) | J8: Unit Cost(10k) | K8: Unit Cost(20k) | L8: Cost (Single) | M8: Unit Cost (100) | N8: Cost (1k) | O8: Cost (10k) | P8: Cost (20k)
A9: 1 | B9: Temp/Humidity BME280 | E9: 1 | F9: https://www.digikey.com/en/products/detail/bosch-sensortec/BME280/6136306?s=N4IgTCBcDaIEYFsCmACMAOADCAugXyA | G9: 9 | H9: 4.9 | I9: =G9*$I$7 -> 6.75 | J9: =I9*$J$7 -> 5.0625 | K9: =J9*$K$7 -> 4.05 | L9: =BOMCost!$E9*BOMCost!$G9 -> 9 | M9: 4.9 | N9: =BOMCost!$E9*1000*BOMCost!$I9 -> 6750 | O9: =BOMCost!$E9*10000*BOMCost!$J9 -> 50625 | P9: =BOMCost!$E9*20000*BOMCost!$K9 -> 81000
A10: 2 | B10: PM2.5 | E10: 1 | F10: https://www.digikey.com/en/products/detail/honeywell-sensing-and-productivity-solutions/HPMA115S0-XXX/7202204 | I10: =G10*$I$7 -> 0 | J10: =I10*$J$7 -> 0 | K10: =J10*$K$7 -> 0 | L10: =BOMCost!$E10*BOMCost!$G10 -> 0 | M10: 25 | N10: =BOMCost!$E10*1000*BOMCost!$I10 -> 0 | O10: =BOMCost!$E10*10000*BOMCost!$J10 -> 0 | P10: =BOMCost!$E10*20000*BOMCost!$K10 -> 0
A11: 4 | B11: BOM SensorBox | E11: 1 | G11: =3 -> 3 | H11: 2 | I11: =G11*$I$7 -> 2.25 | J11: =I11*$J$7 -> 1.6875 | K11: =J11*$K$7 -> 1.35 | L11: =BOMCost!$E11*BOMCost!$G11 -> 3 | M11: 2 | N11: =BOMCost!$E11*1000*BOMCost!$I11 -> 2250 | O11: =BOMCost!$E11*10000*BOMCost!$J11 -> 16875 | P11: =BOMCost!$E11*20000*BOMCost!$K11 -> 27000
A12: 5 | B12: Enclosure + Customization | E12: 1 | F12: altinkaya | G12: 12 | H12: 6.5 | I12: =G12*$I$7 -> 9 | J12: =I12*$J$7 -> 6.75 | K12: =J12*$K$7 -> 5.4 | L12: =BOMCost!$E12*BOMCost!$G12 -> 12 | M12: 6.5 | N12: =BOMCost!$E12*1000*BOMCost!$I12 -> 9000 | O12: =BOMCost!$E12*10000*BOMCost!$J12 -> 67500 | P12: =BOMCost!$E12*20000*BOMCost!$K12 -> 108000
A13: 6 | B13: BOM Sensor Board | E13: 1 | G13: 25 | H13: 20 | I13: =G13*$I$7 -> 18.75 | J13: =I13*$J$7 -> 14.0625 | K13: =J13*$K$7 -> 11.25 | L13: =BOMCost!$E13*BOMCost!$G13 -> 25 | M13: 1.55 | N13: =BOMCost!$E13*1000*BOMCost!$I13 -> 18750 | O13: =BOMCost!$E13*10000*BOMCost!$J13 -> 140625 | P13: =BOMCost!$E13*20000*BOMCost!$K13 -> 225000
A15: 7 | B15: Battery | E15: 1 | F15: https://urun.n11.com/sarj-edilebilen-pil/panasonic-ncr18650b-37v-3400mah-li-ion-sarjli-pil-P107335109?gclid=Cj0KCQiA3dTQBRDnARIsAGKSflnsqduzgX_5Q6ZpAy8g7ChcntG3MRcp9TfPmRmMkBdA9apiIYLxwckaAtYrEALw_wcB&gclsrc=aw.ds | G15: 20 | H15: 18 | I15: =G15*$I$7 -> 15 | J15: =I15*$J$7 -> 11.25 | K15: =J15*$K$7 -> 9 | L15: =BOMCost!$E15*BOMCost!$G15 -> 20 | M15: 18 | N15: =BOMCost!$E15*1000*BOMCost!$I15 -> 15000 | O15: =BOMCost!$E15*10000*BOMCost!$J15 -> 112500 | P15: =BOMCost!$E15*20000*BOMCost!$K15 -> 180000
A16: 8 | B16: Solar Panel | E16: 1 | F16: https://urun.n11.com/gunes-enerjisi/gunes-enerji-paneli-solar-6v-15w-P198769898 | G16: 5 | H16: 4.5 | I16: =G16*$I$7 -> 3.75 | J16: =I16*$J$7 -> 2.8125 | K16: =J16*$K$7 -> 2.25 | L16: =BOMCost!$E16*BOMCost!$G16 -> 5 | M16: 4.5 | N16: =BOMCost!$E16*1000*BOMCost!$I16 -> 3750 | O16: =BOMCost!$E16*10000*BOMCost!$J16 -> 28125 | P16: =BOMCost!$E16*20000*BOMCost!$K16 -> 45000
A17: 9 | B17: Enclosure + Customization | E17: 1 | F17: altinkaya | G17: 12 | H17: 6.5 | I17: =G17*$I$7 -> 9 | J17: =I17*$J$7 -> 6.75 | K17: =J17*$K$7 -> 5.4 | L17: =BOMCost!$E17*BOMCost!$G17 -> 12 | M17: 6.5 | N17: =BOMCost!$E17*1000*BOMCost!$I17 -> 9000 | O17: =BOMCost!$E17*10000*BOMCost!$J17 -> 67500 | P17: =BOMCost!$E17*20000*BOMCost!$K17 -> 108000
A18: 11 | B18: BOM Core Board | E18: 1 | G18: 50 | H18: 45 | I18: =G18*$I$7 -> 37.5 | J18: =I18*$J$7 -> 28.125 | K18: =J18*$K$7 -> 22.5 | L18: =BOMCost!$E18*BOMCost!$G18 -> 50 | M18: 45 | N18: =BOMCost!$E18*1000*BOMCost!$I18 -> 37500 | O18: =BOMCost!$E18*10000*BOMCost!$J18 -> 281250 | P18: =BOMCost!$E18*20000*BOMCost!$K18 -> 450000
A19: 12 | B19: BOM Core Box | E19: 1 | G19: 5 | H19: 4.5 | I19: =G19*$I$7 -> 3.75 | J19: =I19*$J$7 -> 2.8125 | K19: =J19*$K$7 -> 2.25 | L19: =BOMCost!$E19*BOMCost!$G19 -> 5 | M19: 4.5 | N19: =BOMCost!$E19*1000*BOMCost!$I19 -> 3750 | O19: =BOMCost!$E19*10000*BOMCost!$J19 -> 28125 | P19: =BOMCost!$E19*20000*BOMCost!$K19 -> 45000
A21: 13 | B21: WIBxx Module (bc92+esp32) | E21: 1 | G21: 19 | H21: 15.87 | I21: =G21*$I$7 -> 14.25 | J21: =I21*$J$7 -> 10.6875 | K21: =J21*$K$7 -> 8.55 | L21: =BOMCost!$E21*BOMCost!$G21 -> 19 | M21: 15.87 | N21: =BOMCost!$E21*1000*BOMCost!$I21 -> 14250 | O21: =BOMCost!$E21*10000*BOMCost!$J21 -> 106875 | P21: =BOMCost!$E21*20000*BOMCost!$K21 -> 171000
A23: 14 | B23: Alu Body + Fastener + Customization | E23: 1 | G23: 50 | H23: 45 | I23: =G23*$I$7 -> 37.5 | J23: =I23*$J$7 -> 28.125 | K23: =J23*$K$7 -> 22.5 | L23: =BOMCost!$E23*BOMCost!$G23 -> 50 | M23: 33 | N23: =BOMCost!$E23*1000*BOMCost!$I23 -> 37500 | O23: =BOMCost!$E23*10000*BOMCost!$J23 -> 281250 | P23: =BOMCost!$E23*20000*BOMCost!$K23 -> 450000
B25: Comment: | C25: Should we divide PCB - BOM - EMPA like: - Blue: Sensor Box - Green: Core and Peripheral
C26: Core BOM should be revised. | L26: =SUBTOTAL(109,BOMCost!$L$9:$L$23) -> 210 | M26: =SUM(M9:M23)*M29 -> 16732 | N26: =SUBTOTAL(109,BOMCost!$N$9:$N$23) -> 157500 | O26: =SUBTOTAL(109,BOMCost!$O$9:$O$23) -> 1181250 | P26: =SUBTOTAL(109,BOMCost!$P$9:$P$23) -> 1890000
L27: =L26 -> 210 | M27: =M26 -> 16732 | N27: =N26*(1+$K$28) -> 157500 | O27: =O26*(1+$K$28) -> 1181250 | P27: =P26*(1+$K$28) -> 1890000
J28: unit bom cost: | L28: =L26/L29 -> 210 | M28: =M26/M29 -> 167.32 | N28: =N26/N29 -> 157.5 | O28: =O26/O29 -> 118.125 | P28: =P26/P29 -> 94.5
L29: 1 | M29: 100 | N29: 1000 | O29: 10000 | P29: 20000
J31: Sensor Box: | L31: =SUM(L9:L13) -> 49 | M31: =SUM(M9:M13)*M29 -> 3995 | N31: =SUM(N9:N13) -> 36750 | O31: =SUM(O9:O13) -> 275625 | P31: =SUM(P9:P13) -> 441000
J32: unit SB bom cost: | L32: =L31/$L$29 -> 49 | M32: =M31/M29 -> 39.95 | N32: =N31/$N$29 -> 36.75 | O32: =O31/$O$29 -> 27.5625 | P32: =P31/$P$29 -> 22.05
J34: Core: | L34: =SUM(L15:L21) -> 111 | M34: =SUM(M14:M21)*M29 -> 9437 | N34: =SUM(N15:N23) -> 120750 | O34: =SUM(O15:O23) -> 905625 | P34: =SUM(P15:P18) -> 783000
J35: unit Core bom cost: | L35: =L34/$L$29 -> 111 | M35: =M34/M29 -> 94.37 | N35: =N34/$N$29 -> 120.75 | O35: =O34/$O$29 -> 90.5625 | P35: =P34/$P$29 -> 39.15
J37: Peripheral | L37: =0.5*L29/'Live-currencies'!A2 -> 0.025 | M37: =0.5*M29/'Live-currencies'!A2 -> 2.5 | N37: =0.5*I7*N29/'Live-currencies'!A2 -> 18.75 | O37: =0.5*I7*J7*O29/'Live-currencies'!A2 -> 140.625 | P37: =0.5*I7*J7*K7*P29/'Live-currencies'!A2 -> 225
J38: Per. Bom cost: | L38: =L37/$L$29 -> 0.025 | M38: =M37/$M$29 -> 0.025 | N38: =N37/$N$29 -> 0.01875 | O38: =O37/$O$29 -> 0.0140625 | P38: =P37/$P$29 -> 0.01125

Sheet SupportCost
A1: Airqoon - Support Cost
A3: Cost Item | B3: allocated resources in man/day | C3: month | E3: total cost
A4: Software Developer for Support | B4: 4 | C4: 12 | E4: =B4*ResearchAndDevCost!$L$5*C4 -> 7680
D8: Overall: | E8: =SUM(E4:E7) -> 7680

Sheet COGS
A1: Airqoon - Cost of Goods Sold (COGS)
B3: Cost Item | D3: per device cost (for 10) | E3: per device cost (for 100) | F3: per device cost (for 1k) | G3: per device cost (for 10k) | H3: number of units | I3: total cost | J3: Comments
A4: Manufacturing Cost | B4: PCB (Core) | D4: 2.4 | E4: 2.4 | F4: 0.7 | G4: 0.45 | H4: 1000 | I4: =F4*H4 -> 700
B5: PCB (Peripheral) | D5: 1.7 | E5: 1.7 | F5: 0.2 | G5: 0.2 | H5: 1000 | I5: =F5*H5 -> 200
B6: PCB (Sensor Box) | D6: 1.3 | E6: 1.3 | F6: 0.2 | G6: 0.2 | H6: 1000 | I6: =F6*H6 -> 200
B7: Pick-n-Place (sum-up) | D7: =5+2+2 -> 9 | E7: 9 | F7: 1.1 | G7: 0.8 | H7: 1000 | I7: =F7*H7 -> 1100
B8: Tests | D8: 15 | E8: 10 | F8: 5 | G8: 2.5 | H8: 1000 | I8: =F8*H8 -> 5000
C11: subtotal: | D11: =SUM(D4:D10) -> 29.4 | E11: =SUM(E4:E10) -> 24.4 | F11: =SUM(F4:F10) -> 7.2 | G11: =SUM(G4:G10) -> 4.15 | I11: =SUM(I4:I10) -> 7200
F13: minimum shipment quantity
F14: 10
B15: Cost Item | D15: per device cost (for 10) | E15: per device cost (for 100) | F15: per device cost (for 1k) | G15: per device cost (for 10k) | H15: number of units | I15: total cost | J15: Comments
A16: Logistics | B16: Transportation (China2Turkey) | D16: 4 | E16: 0.9 | F16: 0.1 | G16: 0.05 | H16: 1000 | I16: =F16*H16 -> 100
B17: Shipping (Inovatink2Customer) | D17: 10 | E17: 5 | F17: =1/F14 -> 0.1 | G17: 0.01 | H17: 1000 | I17: =F17*H17 -> 100
B18: Warehousing | D18: 2 | E18: 2 | F18: 0.01 | G18: 0.001 | H18: 1000 | I18: =F18*H18 -> 10
B19: Customs | D19: =2300/ 'Live-currencies'!A2 /10 -> 11.5 | E19: =2300/'Live-currencies'!A2/100 -> 1.15 | F19: =2300/'Live-currencies'!A2 /1000 -> 0.115 | G19: =2300/'Live-currencies'!A2 /10000 -> 0.0115 | H19: 1000 | I19: =F19*H19 -> 115 | J19: (cost*0.2)usd + 1200TL
C22: subtotal: | D22: =SUM(D16:D21) -> 27.5 | E22: =SUM(E16:E21) -> 9.05 | F22: =SUM(F16:F21) -> 0.325 | G22: =SUM(G16:G21) -> 0.0725 | I22: =SUM(I16:I21) -> 325
C25: Percent of defected device among a batch of 1k | F25: number of devices which covers initial R&D Cost
C26: 0.1 | F26: 500
B27: Cost Item | D27: per device cost (for 10) | E27: per device cost (for 100) | F27: per device cost (for 1k) | G27: per device cost (for 10k) | H27: number of units | I27: total cost | J27: Comments
B28: Manufacturing Cost | D28: =D11 -> 29.4 | E28: =E11 -> 24.4 | F28: =F11 -> 7.2 | G28: =G11 -> 4.15 | H28: 1000 | I28: =F28*H28 -> 7200
B29: Logistics Cost | D29: =D22 -> 27.5 | E29: =E22 -> 9.05 | F29: =F22 -> 0.325 | G29: =G22 -> 0.0725 | H29: 1000 | I29: =F29*H29 -> 325
B30: Defected Product Cost | D30: =($C$26*BOMCost!L28+D17) -> 31 | E30: =($C$26*BOMCost!L28+E17) -> 26 | F30: =($C$26*BOMCost!N28+$E$17) -> 20.75 | G30: =($C$26*BOMCost!O28+$F$17) -> 11.9125 | H30: 1000 | I30: =F30*H30 -> 20750
B31: Support Cost | D31: =SupportCost!$E$8/1000 -> 7.68 | E31: =SupportCost!$E$8/1000 -> 7.68 | F31: =SupportCost!$E$8/1000 -> 7.68 | G31: =SupportCost!$E$8/10000 -> 0.768 | H31: 1000 | I31: =F31*H31 -> 7680 | J31: for 10 and 100, 50 and 100 device will cover support cost respectively
B32: R&D Cost (HW) | H32: 1000 | I32: =F32*H32 -> 0 | J32: for 10 and 100, 250 device will cover initial HW R&D Cost
B33: R&D Cost (SW) | H33: 1000 | I33: =F33*H33 -> 0 | J33: for 10 and 100, 250 device will cover initial SW R&D Cost
B34: BOM Cost (Core) | D34: =BOMCost!L35 -> 111 | E34: =BOMCost!L35-8 -> 103 | F34: =BOMCost!N35 -> 120.75 | G34: =BOMCost!O35 -> 90.5625 | H34: 1000 | I34: =F34*H34 -> 120750
B35: BOM Cost (Sensor Box) | D35: =BOMCost!L32 -> 49 | E35: =BOMCost!L32 -> 49 | F35: =BOMCost!N32 -> 36.75 | G35: =BOMCost!O32 -> 27.5625 | H35: 1000 | I35: =F35*H35 -> 36750
B36: Aluminum Enclosure Cost | D36: =BOMCost!G23 -> 50 | E36: 28 | F36: 25 | G36: 20
C38: w/o Sensor Box | D38: =D40-D35 -> 256.58 | E38: =E40-E35 -> 198.13 | F38: =F40-F35 -> 181.705 | G38: =G40-G35 -> 127.4655
C40: Overall: | D40: =SUM(D28:D37) -> 305.58 | E40: =SUM(E28:E37) -> 247.13 | F40: =SUM(F28:F37) -> 218.455 | G40: =SUM(G28:G37) -> 155.028 | I40: =SUM(I28:I37) -> 193455

Sheet Total Costs
A1: Total Costs
B2: 10 | C2: 50 | D2: 100 | E2: 500 | F2: 1000 | G2: 5000 | H2: comments
A3: Sensor Unit Cost | B3: =COGS!D40 -> 305.58 | C3: =(B3+D3)/2 -> 276.355 | D3: =COGS!E40 -> 247.13 | E3: =(D3+F3)/2 -> 232.7925 | F3: =COGS!F40 -> 218.455 | G3: =(#REF! + F3) /2 -> #REF!
A4: Cloud Cost (per device per month) | B4: 2.27 | C4: 2.27 | D4: 2.27 | E4: 0.23 | F4: 0.23 | G4: 0.04
A5: Network Cost (per device per month) | B5: 2 | C5: 2 | D5: 2 | E5: 1 | F5: 0.5 | G5: 0.5
A6: Total Cloud + Network Cost (months) | B6: =SUM(B4:B5) -> 4.27 | C6: =SUM(C4:C5) -> 4.27 | D6: =SUM(D4:D5) -> 4.27 | E6: =SUM(E4:E5) -> 1.23 | F6: =SUM(F4:F5) -> 0.73 | G6: =SUM(G4:G5) -> 0.54
A7: Total Cloud + Network Cost (annual) | B7: =B6*12 -> 51.24 | C7: =C6*12 -> 51.24 | D7: =D6*12 -> 51.24 | E7: =E6*12 -> 14.76 | F7: =F6*12 -> 8.76 | G7: =G6*12 -> 6.48
A8: Additional Sensor Cost base + each sensor | G8: =SUM('Sensor Costs'!$G$74,'Sensor Costs'!$G$75,'Sensor Costs'!$G$85) -> 1217.448
A10: Operational Cost | B10: =B9*B14 -> 0 | C10: =C9*C14 -> 0 | D10: =D9*D14 -> 0 | E10: =E9*E14 -> 0 | F10: =F9*F14 -> 0
A11: with Annual Inflation (USD) Contribution | B11: =(B9+B10)*($B$15) -> 0 | C11: =(C9+C10)*($B$15) -> 0 | D11: =(D9+D10)*($B$15) -> 0 | E11: =(E9+E10)*($B$15) -> 0 | F11: =(F9+F10)*($B$15) -> 0 | G11: =(G9+G10)*($B$15) -> 0
A12: Total Unit Cost | B12: =SUM(B3,B7,B8) -> 356.82 | C12: =SUM(C3,C7,C8) -> 327.595 | D12: =SUM(D3,D7,D8) -> 298.37 | E12: =SUM(E3,E7) -> 247.5525 | F12: =SUM(F3,F7) -> 227.215
A14: Operational cost percentage | B14: 0.05 | C14: 0.075 | D14: 0.1 | E14: 0.1 | F14: 0.15
A15: Annual Inflation rate (USD) | B15: 0.1
A17: Day 1 Manufacturing Cost | B17: =B12*B2 -> 3568.2 | C17: =C12*C2 -> 16379.75 | D17: =D12*D2 -> 29837 | E17: =E12*E2 -> 123776.25 | F17: =F12*F2 -> 227215
A20: Upcoming years annual maintenance cost | B20: =B9*B2 -> 0 | C20: =C9*C2 -> 0 | D20: =D9*D2 -> 0 | E20: =E9*E2 -> 0 | F20: =F9*F2 -> 0
B27: =100*1+BOMCost!$L$32 -> 149 | C27: =80*1+BOMCost!$L$32 -> 129 | D27: =70*1+BOMCost!$L$32 -> 119 | E27: =60*1+BOMCost!$L$32 -> 109 | F27: =50*1+BOMCost!$N$32 -> 86.75
B29: =100*4+BOMCost!$L$32 -> 449 | C29: =80*4+BOMCost!$L$32 -> 369 | D29: =70*4+BOMCost!$L$32 -> 329 | E29: =60*4+BOMCost!$L$32 -> 289 | F29: =50*4+BOMCost!$N$32 -> 236.75

Sheet Sensor Costs
B1: POUND/USD | C1: 1.28
B2: EUR/USD | C2: 1.11
B3: KDV | C3: 0.2 | H3: customs + logistics margin
B6: Company | C6: UKDynament | G6: Airqoon prefered | H6: 0.4
B7: Quote Date | C7: 45078
B8: N2O | D8: =144 -> 144 | E8: =D8*$C$1 -> 184.32 | F8: =E8*(1+$C$3) -> 221.184 | G8: =F8*(1+$H$12) -> 552.96
B9: CO2 - extended range | D9: 144 | E9: =D9*$C$1 -> 184.32 | F9: =E9*(1+$C$3) -> 221.184 | G9: =F9*(1+$H$12) -> 552.96
B10: CH4 | D10: 144 | E10: =D10*$C$1 -> 184.32 | F10: =E10*(1+$C$3) -> 221.184 | G10: =F10*(1+$H$12) -> 552.96
B12: Company | C12: Alphansense | G12: Airqoon prefered | H12: 1.5
B13: Quote Date | C13: 45323
B14: CO-B4 | D14: 78.07 | E14: =D14*$C$2 -> 86.6577 | F14: =E14*(1+$C$3) -> 103.98924 | G14: =F14*(1+$H$12) -> 259.9731 | I14: 8 | J14: =E14*I14 -> 693.2616
B15: SO2-B4 | D15: 82.21 | E15: =D15*$C$2 -> 91.2531 | F15: =E15*(1+$C$3) -> 109.50372 | G15: =F15*(1+$H$12) -> 273.7593 | I15: 8 | J15: =E15*I15 -> 730.0248
B16: 4-Electrode ISB (CO, H2S, SO2, VOC @ Zero Bias) | D16: 85.7 | E16: =D16*$C$2 -> 95.127 | F16: =E16*(1+$C$3) -> 114.1524 | G16: =F16*(1+$H$12) -> 285.381 | I16: 16 | J16: =E16*I16 -> 1522.032
B17: NO2-B43F | D17: 56.96 | E17: =D17*$C$2 -> 63.2256 | F17: =E17*(1+$C$3) -> 75.87072 | G17: =F17*(1+$H$12) -> 189.6768 | I17: 8 | J17: =E17*I17 -> 505.8048
B18: OX-B431 | D18: 51.97 | E18: =D18*$C$2 -> 57.6867 | F18: =E18*(1+$C$3) -> 69.22404 | G18: =F18*(1+$H$12) -> 173.0601 | I18: 8 | J18: =E18*I18 -> 461.4936
B19: 4-Electrode ISB (NO2, O3) | D19: 81.58 | E19: =D19*$C$2 -> 90.5538 | F19: =E19*(1+$C$3) -> 108.66456 | G19: =F19*(1+$H$12) -> 271.6614 | I19: 16 | J19: =E19*I19 -> 1448.8608
B20: PID-AY5 VOC (0-20ppm) 10.6eV Lamp | D20: 399.23 | E20: =D20*$C$2 -> 443.1453 | F20: =E20*(1+$C$3) -> 531.77436 | G20: =F20*(1+$H$12) -> 1329.4359
B21: PID PCB Mounting Board | D21: 35.84 | E21: =D21*$C$2 -> 39.7824 | F21: =E21*(1+$C$3) -> 47.73888 | G21: =F21*(1+$H$12) -> 119.3472
B22: Misc for ISB (Mount&Calibration) | D22: 6.7 | E22: =D22*$C$2 -> 7.437 | F22: =E22*(1+$C$3) -> 8.9244 | G22: =F22*(1+$H$12) -> 22.311 | I22: 32 | J22: =E22*I22 -> 237.984
J23: =SUM(J14:J22) -> 5599.4616
B24: Quote Date | C24: 45292
B25: CO-B4 | D25: 75.6 | E25: =D25*$C$2 -> 83.916 | F25: =E25*(1+$C$3) -> 100.6992 | G25: =F25*(1+$H$12) -> 251.748
B26: SO2-B4 | D26: 82.9 | E26: =D26*$C$2 -> 92.019 | F26: =E26*(1+$C$3) -> 110.4228 | G26: =F26*(1+$H$12) -> 276.057
B27: 4-Electrode ISB (CO, H2S, SO2, VOC @ Zero Bias) | D27: 83.2 | E27: =D27*$C$2 -> 92.352 | F27: =E27*(1+$C$3) -> 110.8224 | G27: =F27*(1+$H$12) -> 277.056
B28: NO2-B43F | D28: 55.3 | E28: =D28*$C$2 -> 61.383 | F28: =E28*(1+$C$3) -> 73.6596 | G28: =F28*(1+$H$12) -> 184.149
B29: OX-B431 | D29: 66.9 | E29: =D29*$C$2 -> 74.259 | F29: =E29*(1+$C$3) -> 89.1108 | G29: =F29*(1+$H$12) -> 222.777
B30: 4-Electrode ISB (NO2, O3) | D30: 79.2 | E30: =D30*$C$2 -> 87.912 | F30: =E30*(1+$C$3) -> 105.4944 | G30: =F30*(1+$H$12) -> 263.736
B31: NH3-B1 | D31: 78.5 | E31: =D31*$C$2 -> 87.135 | F31: =E31*(1+$C$3) -> 104.562 | G31: =F31*(1+$H$12) -> 261.405
B32: 4-Electrode ISB (NO, ETO, NH3, VOC @ +200mV Bias) | D32: 79.2 | E32: =D32*$C$2 -> 87.912 | F32: =E32*(1+$C$3) -> 105.4944 | G32: =F32*(1+$H$12) -> 263.736
B33: Misc for ISB (Mount&Calibration) | D33: 6.3 | E33: =D33*$C$2 -> 6.993 | F33: =E33*(1+$C$3) -> 8.3916 | G33: =F33*(1+$H$12) -> 20.979
B35: Quote Date | C35: 45265
B36: OPC-N3 | D36: 410 | E36: =D36*$C$2 -> 455.1 | F36: =E36*(1+$C$3) -> 546.12 | G36: =F36*(1+$H$12) -> 1365.3
B37: SPI Connector | D37: 7 | E37: =D37*$C$2 -> 7.77 | F37: =E37*(1+$C$3) -> 9.324 | G37: =F37*(1+$H$12) -> 23.31
B39: Quote Date | C39: 45174
B40: CO-B4 | D40: 75.6 | E40: =D40*$C$2 -> 83.916 | F40: =E40*(1+$C$3) -> 100.6992 | G40: =F40*(1+$H$12) -> 251.748
B41: SO2-B4 | D41: 79.8 | E41: =D41*$C$2 -> 88.578 | F41: =E41*(1+$C$3) -> 106.2936 | G41: =F41*(1+$H$12) -> 265.734
B42: NO2-B43F | D42: 55.3 | E42: =D42*$C$2 -> 61.383 | F42: =E42*(1+$C$3) -> 73.6596 | G42: =F42*(1+$H$12) -> 184.149
B43: 4-Electrode ISB (NO2, OX) | D43: 79.2 | E43: =D43*$C$2 -> 87.912 | F43: =E43*(1+$C$3) -> 105.4944 | G43: =F43*(1+$H$12) -> 263.736
B44: 4-Electrode ISB (CO, SO2) | D44: 83.2 | E44: =D44*$C$2 -> 92.352 | F44: =E44*(1+$C$3) -> 110.8224 | G44: =F44*(1+$H$12) -> 277.056
B45: OX-B431 | D45: 66.9 | E45: =D45*$C$2 -> 74.259 | F45: =E45*(1+$C$3) -> 89.1108 | G45: =F45*(1+$H$12) -> 222.777
...

Sheet nextpm-check
E2: KDV-raw | F2: 0.2
E3: KDV-customs | F3: 0.21
E4: usd/try | F4: 34
D7: single unit | E7: n of units | F7: customs representative fee | G7: customs(ordino) | H7: customs(ardiye) | I7: shipping | J7: customs(docs) | K7: stamp tax :) | L7: KDV | M7: one-time-costs | N7: total cost
C8: from KMC | D8: 95 | E8: 20 | F8: 0 | G8: 0 | H8: 0 | I8: 0 | J8: 0 | K8: 0 | L8: =D8*F2 -> 19 | M8: =K8+J8+I8+H8+G8+F8 -> 0 | N8: =(D8+L8)*E8+M8 -> 2280
O9: =N8-N10 -> 155.77647
C10: from manufacturer | D10: 74.5 | E10: 20 | F10: =3300/F4 -> 97.058824 | G10: =1350/F4 -> 39.705882 | H10: =2800/F4 -> 82.352941 | I10: 65 | J10: =480/F4 -> 14.117647 | K10: =785/F4 -> 23.088235 | L10: =D10*F3 -> 15.645 | M10: =K10+J10+I10+H10+G10+F10 -> 321.32353 | N10: =(D10+L10)*E10+M10 -> 2124.2235

Sheet Annual Services Costs
C2: POUND/USD | D2: 1.28
C3: EUR/USD | D3: 1.087
C4: KDV | D4: 0.2
C5: USD/TL | D5: 35
B7: Temel Maliyet Kalemleri
B8: No | C8: Maliyet | D8: Ücret | E8: Açıklama | F8: Yuvarlama ve Yıllık
B9: 1 | C9: İletişim | D9: =20/D5 -> 0.57142857 | E9: GSM Operatör Maliyeti - Aylık | F9: =1*12 -> 12
B10: 2 | C10: Bulut | D10: 750 | E10: Tüm bulut altyapı maliyeti AWS - Aylık | F10: =D10*12/250 -> 36
B11: 3 | C11: Kargo | D11: =250*2/D5 -> 14.285714 | E11: Bakım için geldi, bakımdan geri döndü (git/gel) | F11: 25
B12: 4 | C12: Kurulum | D12: =4500/D5 -> 128.57143 | E12: Gittik cihazları kurduk. - Tekil | F12: 175
B13: 5 | C13: Raporlama | D13: =10 + 2000 / D5 -> 67.142857 | E13: Claude maliyeti, Ayşe (adam/saat) - Aylık | F13: =10 * 12 + 2000 / D5 * 12 -> 805.71429
B14: 6 | C14: Tekrar Kalibrasyon | D14: =(2500 + 2500) / D5 -> 142.85714 | E14: Kalibrasyon için cihazların götürülüp kurulması, kalibrasyonun yapılması, kalibrasyon raporunun çıkarılması, sonra tekrardan alınması Tekil (gülkan ayrı, orhun/eren ayrı) | F14: =150 -> 150
B15: 7 | C15: Bakım | D15: =2500 / D5 -> 71.428571 | E15: Cihazın temizlenmesi, tekrar boyanmasi, parça değişimi ? - Tekil | F15: 75

Sheet Sensor Box Prices
B5: Sensor Box Costs
B6: No | C6: Name | D6: Cost
B7: 1 | C7: box | D7: 20
B8: 2 | C8: socket | D8: 5
B9: 3 | C9: pcb | D9: 15
B10: 4 | C10: 3d-printed parts | D10: 10
B11: 5 | C11: nextpm sensor | D11: 115
B12: 6 | C12: sensor cabling | D12: 1.5
B13: 7 | C13: bolt & distance | D13: 3
C14: subtotal: | D14: =SUM(D7:D13) -> 169.5
B17: Single Gas cost in average | K17: through recycling we receive
B18: No | C18: Name | D18: Cost | K18: 1 | L18: pcb | M18: 15
B19: 1 | C19: ISB | D19: 110 | F19: recycled material fault percentage | G19: =0.2 -> 0.2 | K19: 2 | L19: isb | M19: 110
B20: 2 | C20: EC Cell | D20: 90
C21: subtotal: | D21: =SUM(D19:D20) -> 200
C23: rough costs | D23: indended price | E23: rough costs / final price | F23: recycled material cost | G23: cost after recycle | H23: 2nd price w.r.t. Recycled materials | I23: rounded price
B24: SB-Lite | C24: =D14 -> 169.5 | D24: 450 | E24: =D24/C24 -> 2.6548673 | F24: =M18*(1-$G$19) -> 12 | G24: =C24-F24 -> 157.5 | H24: 450 | I24: 450 | J24: =I24/G24 -> 2.8571429
B25: SB-GAS-1 | C25: =D14+D21*1 -> 369.5 | D25: =D24+350 -> 800 | E25: =D25/C25 -> 2.165088 | F25: =(M18+M19)*(1-$G$19) -> 100 | G25: =C25-F25 -> 269.5 | H25: =D25-F25 -> 700 | I25: 750 | J25: =I25/G25 -> 2.7829314
B26: SB-GAS-2 | C26: =D14+D21*2 -> 569.5 | D26: =D25+350 -> 1150 | E26: =D26/C26 -> 2.0193152 | F26: =(M18+M19*2)*(1-$G$19) -> 188 | G26: =C26-F26 -> 381.5 | H26: =D26-F26 -> 962 | I26: 1050 | J26: =I26/G26 -> 2.7522936
B27: SB-GAS-3 | C27: =D14+D21*3 -> 769.5 | D27: =D26+350 -> 1500 | E27: =D27/C27 -> 1.9493177 | F27: =(M18+M19*3)*(1-$G$19) -> 276 | G27: =C27-F27 -> 493.5 | H27: =D27-F27 -> 1224 | I27: 1350 | J27: =I27/G27 -> 2.7355623
B28: SB-GAS-4 | C28: =D14+D21*4 -> 969.5 | D28: =D27+350 -> 1850 | E28: =D28/C28 -> 1.9082001 | F28: =(M18+M19*4)*(1-$G$19) -> 364 | G28: =C28-F28 -> 605.5 | H28: =D28-F28 -> 1486 | I28: 1650 | J28: =I28/G28 -> 2.7250206

Sheet Prices
J2: Unique Gases | M2: USD/TL (rent) | N2: 36
B3: Direct sales model | C3: 10-costs | D3: 10 | E3: 10 (calculated price / cost) | F3: 10 | G3: 10 (rounded price / cost) | H3: 10 | J3: Direct sales model | K3: 10 | M3: USD/TL (direct sale) | N3: 34
B4: PM + T + RH | C4: ='Total Costs'!B12 -> 356.82 | D4: =Models!C8 -> 1784.1 | E4: =(D4)/C4 -> 5 | F4: 2250 | G4: =F4/C4 -> 6.3057004 | H4: =$N$3*F4 -> 76500 | J4: PM + T + RH + VOC | K4: =F4+'Sensor Costs'!G81 -> 3540.708 | L4: 3150
B5: PM + T + RH + 1 GAS* (ISB) | C5: =C4+SUM('Sensor Costs'!F26,'Sensor Costs'!F27,'Sensor Costs'!F33) -> 586.4568 | D5: =D4+SUM('Sensor Costs'!G26,'Sensor Costs'!G27,'Sensor Costs'!G33) -> 2358.192 | E5: =(D5)/C5 -> 4.0210839 | F5: 3000 | G5: =F5/C5 -> 5.1154663 | H5: =$N$3*F5 -> 102000 | J5: PM + T + RH + H2S | K5: =F4+'Sensor Costs'!G116+'Sensor Costs'!G68+'Sensor Costs'!G67 -> 2744.505 | L5: 2750
B6: PM + T + RH + 2 GAS* (ISB) | C6: =C5+2*SUM('Sensor Costs'!F27,'Sensor Costs'!F28,'Sensor Costs'!F34) -> 955.4208 | D6: =Prices!D4+2*SUM('Sensor Costs'!G26,'Sensor Costs'!G27,'Sensor Costs'!G33) -> 2932.284 | E6: =(D6)/C6 -> 3.0691021 | F6: 3500 | G6: =F6/C6 -> 3.6633073 | H6: =$N$3*F6 -> 119000 | J6: PM + T + RH + VOC + H2S | K6: =F4+'Sensor Costs'!G116+'Sensor Costs'!G68+'Sensor Costs'!G67+'Sensor Costs'!G81 -> 4035.213 | L6: 3400
B7: PM + T + RH + 2 GAS* (AFE-2) | C7: =C4+SUM('Sensor Costs'!$E$49,'Sensor Costs'!$E$50,'Sensor Costs'!$E$53,'Sensor Costs'!$E$54,'Sensor Costs'!$E$54) -> 598.6002 | D7: 2100 | E7: =(D7)/C7 -> 3.5081846
B8: PM + T + RH + 3 GAS* (ISB) | C8: =C6+3*SUM('Sensor Costs'!F28,'Sensor Costs'!F29,'Sensor Costs'!F38) -> 1443.732 | D8: =Prices!D4+3*SUM('Sensor Costs'!G26,'Sensor Costs'!G27,'Sensor Costs'!G33) -> 3506.376 | E8: =(D8)/C8 -> 2.428689 | F8: 4250 | G8: =F8/C8 -> 2.9437596 | H8: =$N$3*F8 -> 144500
B9: PM + T + RH + 4 GAS* (ISB) | C9: =C8+4*SUM('Sensor Costs'!F29,'Sensor Costs'!F30,'Sensor Costs'!F39) -> 2222.1528 | D9: =D4+4*SUM('Sensor Costs'!G26,'Sensor Costs'!G27,'Sensor Costs'!G33) -> 4080.468 | E9: =(D9)/C9 -> 1.836268 | F9: 4750 | G9: =F9/C9 -> 2.1375668 | H9: =$N$3*F9 -> 161500
B10: PM + T + RH + 4 GAS* (AFE-2) | C10: =C4+2*SUM('Sensor Costs'!$E$49,'Sensor Costs'!$E$50,'Sensor Costs'!$E$53,'Sensor Costs'!$E$54,'Sensor Costs'!$E$54) -> 840.3804 | D10: 3000 | E10: =(D10)/C11 -> 1.5975638
B11: Ülkü Hoca Balıklıgöl, 4-GAS, OPC-N3, CO2 | C11: =C4+SUM('Sensor Costs'!F36,'Sensor Costs'!F14,'Sensor Costs'!F16,'Sensor Costs'!F15,'Sensor Costs'!F16,'Sensor Costs'!F17,'Sensor Costs'!F18,'Sensor Costs'!F19,'Sensor Costs'!F19,'Sensor Costs'!F22,'Sensor Costs'!F22,'Sensor Costs'!F22,'Sensor Costs'!F22)+'Sensor Costs'!G137 -> 1877.8592 | D11: =C11*3 -> 5633.5777
J12: Upcoming year service fee (annual) | K12: 500
B13: Upcoming year service fee (annual) | D13: 550 | J13: Ultrasonic Wind Sensor | K13: 1250
B14: *Gas Alternatives - Set 1: NO,NO2,O3, CO, SO2 | J14: Mechanical Wind Sensor | K14: 900
B15: **Gas Alternatives - Set 2: H2S, NH3, CH4 | J15: VOC - PID | K15: 750
B16: ***Gas Alternatives - Set 3: VOCs | J16: H2S | K16: 250
B18: Lease Model | D18: 10 | J18: Lease Model | K18: 10
B19: PM + T + RH | C19: 441.52 | D19: =F4/18 -> 125 | F19: 125 | H19: =F19*$N$2 -> 4500 | J19: PM + T + RH + SO2 | K19: 175
B20: PM + T + RH + 1 GAS* (ISB) | C20: 666.39856 | D20: =F5/18 -> 166.66667 | F20: 175 | H20: =F20*$N$2 -> 6300 | J20: PM + T + RH + VOC + H2S | K20: =K6/18 -> 224.1785
B21: PM + T + RH + 2 GAS* (ISB) | C21: 1027.7174 | D21: =F6/18 -> 194.44444 | F21: 200 | H21: =F21*$N$2 -> 7200 | J21: PM + T + RH + VOC + SO2 + H2S | K21: 300
B22: PM + T + RH + 2 GAS* (AFE-2) | C22: 678.29034 | D22: =F8/18 -> 236.11111 | F22: 225 | H22: =F22*$N$2 -> 8100
B23: PM + T + RH + 3 GAS* (ISB) | C23: 1505.9104 | D23: =F9/18 -> 263.88889 | F23: 250 | H23: =F23*$N$2 -> 9000
B24: PM + T + RH + 4 GAS* (ISB) | C24: 2268.2018 | J24: Minimum lease duration | K24: 6 months
B25: PM + T + RH + 4 GAS* (AFE-2) | C25: 915.06068
B26: *Gas Alternatives - Set 1: NO,NO2,O3, CO, SO2
J29: Unique Gases
J30: Direct sales model | K30: 10
J31: PM + T + RH + SO2 | K31: 3000
J32: PM + T + RH + VOC + H2S | K32: 3000
J33: PM + T + RH + VOC + SO2 + H2S | K33: 3000

Sheet Prices-custom
J2: Unique Gases | M2: USD/TL (rent) | N2: 35
B3: Direct sales model | C3: 10-costs | D3: 10 | E3: 10 (calculated price / cost) | F3: 10 | G3: 10 (rounded price / cost) | H3: 10 | J3: Direct sales model | K3: 10 | M3: USD/TL (direct sale) | N3: 33
B4: PM + T + RH | C4: ='Total Costs'!B12 -> 356.82 | D4: =Models!C8 -> 1784.1 | E4: =(D4)/C4 -> 5 | F4: 2250 | G4: =F4/C4 -> 6.3057004 | H4: =$N$3*F4 -> 74250 | J4: PM + T + RH + VOC | K4: =F4+'Sensor Costs'!G81 -> 3540.708 | L4: 3150
B5: PM + T + RH + SEN54 + Noise | C5: =C4+SUM('Sensor Costs'!G134,'Sensor Costs'!G137,'Sensor Costs'!G128) -> 858.42 | D5: =D4+SUM('Sensor Costs'!G134,'Sensor Costs'!G137,'Sensor Costs'!G128) -> 2285.7 | E5: =(D5)/C5 -> 2.6626826 | F5: 3250 | G5: =F5/C5 -> 3.7860255 | H5: =$N$3*F5 -> 107250 | J5: PM + T + RH + H2S | K5: =F4+'Sensor Costs'!G116+'Sensor Costs'!G68+'Sensor Costs'!G67 -> 2744.505 | L5: 2750
J6: Upcoming year service fee (annual) | K6: 500
B7: Upcoming year service fee (annual) | D7: 550 | J7: Ultrasonic Wind Sensor | K7: 1250
B8: *Gas Alternatives - Set 1: NO,NO2,O3, CO, SO2 | J8: Mechanical Wind Sensor | K8: 900
B9: **Gas Alternatives - Set 2: H2S, NH3, CH4 | J9: VOC - PID | K9: 750
B10: ***Gas Alternatives - Set 3: VOCs | J10: H2S | K10: 250
B12: Lease Model | D12: 10 | J12: Lease Model | K12: 10
B13: PM + T + RH | D13: =F4/18 -> 125 | F13: 125 | H13: =F13*$N$2 -> 4375 | J13: PM + T + RH + SO2 | K13: 175
B14: PM + T + RH + 1 GAS* | D14: =F5/18 -> 180.55556 | F14: 175 | H14: =F14*$N$2 -> 6125 | J14: PM + T + RH + VOC + H2S | K14: =#REF!/18 -> #REF!
B15: PM + T + RH + 2 GAS* | D15: =#REF!/18 -> #REF! | F15: 200 | H15: =F15*$N$2 -> 7000 | J15: PM + T + RH + VOC + SO2 + H2S | K15: 300
B16: PM + T + RH + 3 GAS* | D16: =#REF!/18 -> #REF! | F16: 225 | H16: =F16*$N$2 -> 7875
B17: PM + T + RH + 4 GAS* | D17: =#REF!/18 -> #REF! | F17: 250 | H17: =F17*$N$2 -> 8750
B18: *Gas Alternatives: NO, NO2, O3, CO, SO2 | J18: Minimum lease duration | K18: 6 months
J23: Unique Gases
J24: Direct sales model | K24: 10
J25: PM + T + RH + SO2 | K25: 3000
J26: PM + T + RH + VOC + H2S | K26: 3000
J27: PM + T + RH + VOC + SO2 + H2S | K27: 3000

Sheet Models
B3: w/ Sensor Unit (first year)
B4: Gross Margin | C4: 10 | D4: 50 | E4: 100 | F4: 500 | G4: 1000
B5: 2 | C5: ='Total Costs'!B$12*(1+Models!$B5) -> 1070.46 | D5: ='Total Costs'!C$12*(1+Models!$B5) -> 982.785 | E5: ='Total Costs'!D$12*(1+Models!$B5) -> 895.11 | F5: ='Total Costs'!E$12*(1+Models!$B5) -> 742.6575 | G5: ='Total Costs'!F$12*(1+Models!$B5) -> 681.645
B6: 2.5 | C6: ='Total Costs'!B$12*(1+Models!$B6) -> 1248.87 | D6: ='Total Costs'!C$12*(1+Models!$B6) -> 1146.5825 | E6: ='Total Costs'!D$12*(1+Models!$B6) -> 1044.295 | F6: ='Total Costs'!E$12*(1+Models!$B6) -> 866.43375 | G6: ='Total Costs'!F$12*(1+Models!$B6) -> 795.2525
B7: 3 | C7: ='Total Costs'!B$12*(1+Models!$B7) -> 1427.28 | D7: ='Total Costs'!C$12*(1+Models!$B7) -> 1310.38 | E7: ='Total Costs'!D$12*(1+Models!$B7) -> 1193.48 | F7: ='Total Costs'!E$12*(1+Models!$B7) -> 990.21 | G7: ='Total Costs'!F$12*(1+Models!$B7) -> 908.86
B8: 4 | C8: ='Total Costs'!B$12*(1+Models!$B8) -> 1784.1 | D8: ='Total Costs'!C$12*(1+Models!$B8) -> 1637.975 | E8: ='Total Costs'!D$12*(1+Models!$B8) -> 1491.85 | F8: ='Total Costs'!E$12*(1+Models!$B8) -> 1237.7625 | G8: ='Total Costs'!F$12*(1+Models!$B8) -> 1136.075
B10: w/o Sensor Unit (next years)
B11: Gross Margin | C11: 10 | D11: 50 | E11: 100 | F11: 500 | G11: 1000
B12: 2.5 | C12: =SUM('Total Costs'!B$11,'Total Costs'!B$10,'Total Costs'!B$9)*(1+Models!$B12) -> 0 | D12: =SUM('Total Costs'!C$11,'Total Costs'!C$10,'Total Costs'!C$9)*(1+Models!$B12) -> 0 | E12: =SUM('Total Costs'!D$11,'Total Costs'!D$10,'Total Costs'!D$9)*(1+Models!$B12) -> 0 | F12: =SUM('Total Costs'!E$11,'Total Costs'!E$10,'Total Costs'!E$9)*(1+Models!$B12) -> 0 | G12: =SUM('Total Costs'!F$11,'Total Costs'!F$10,'Total Costs'!F$9)*(1+Models!$B12) -> 0
B13: 3 | C13: =SUM('Total Costs'!B$11,'Total Costs'!B$10,'Total Costs'!B$9)*(1+Models!$B13) -> 0 | D13: =SUM('Total Costs'!C$11,'Total Costs'!C$10,'Total Costs'!C$9)*(1+Models!$B13) -> 0 | E13: =SUM('Total Costs'!D$11,'Total Costs'!D$10,'Total Costs'!D$9)*(1+Models!$B13) -> 0 | F13: =SUM('Total Costs'!E$11,'Total Costs'!E$10,'Total Costs'!E$9)*(1+Models!$B13) -> 0 | G13: =SUM('Total Costs'!F$11,'Total Costs'!F$10,'Total Costs'!F$9)*(1+Models!$B13) -> 0
B14: 3.5 | C14: =SUM('Total Costs'!B$11,'Total Costs'!B$10,'Total Costs'!B$9)*(1+Models!$B14) -> 0 | D14: =SUM('Total Costs'!C$11,'Total Costs'!C$10,'Total Costs'!C$9)*(1+Models!$B14) -> 0 | E14: =SUM('Total Costs'!D$11,'Total Costs'!D$10,'Total Costs'!D$9)*(1+Models!$B14) -> 0 | F14: =SUM('Total Costs'!E$11,'Total Costs'!E$10,'Total Costs'!E$9)*(1+Models!$B14) -> 0 | G14: =SUM('Total Costs'!F$11,'Total Costs'!F$10,'Total Costs'!F$9)*(1+Models!$B14) -> 0
B15: 4 | C15: =SUM('Total Costs'!B$11,'Total Costs'!B$10,'Total Costs'!B$9)*(1+Models!$B15) -> 0 | D15: =SUM('Total Costs'!C$11,'Total Costs'!C$10,'Total Costs'!C$9)*(1+Models!$B15) -> 0 | E15: =SUM('Total Costs'!D$11,'Total Costs'!D$10,'Total Costs'!D$9)*(1+Models!$B15) -> 0 | F15: =SUM('Total Costs'!E$11,'Total Costs'!E$10,'Total Costs'!E$9)*(1+Models!$B15) -> 0 | G15: =SUM('Total Costs'!F$11,'Total Costs'!F$10,'Total Costs'!F$9)*(1+Models!$B15) -> 0
B17: Lease Model
B18: Gross Margin | C18: 10 | D18: 50 | E18: 100 | F18: 500 | G18: 1000
B19: 4 | C19: =(SUM(C12+C5)/2) -> 535.23 | D19: =(SUM(D12+D5)/2) -> 491.3925 | E19: =(SUM(E12+E5)/2) -> 447.555 | F19: =(SUM(F12+F5)/2) -> 371.32875 | G19: =(SUM(G12+G5)/2) -> 340.8225
B20: 4.5 | C20: =(SUM(C13+C6)/2) -> 624.435 | D20: =(SUM(D13+D6)/2) -> 573.29125 | E20: =(SUM(E13+E6)/2) -> 522.1475 | F20: =(SUM(F13+F6)/2) -> 433.21687 | G20: =(SUM(G13+G6)/2) -> 397.62625
B21: 5 | C21: =(SUM(C14+C7)/2) -> 713.64 | D21: =(SUM(D14+D7)/2) -> 655.19 | E21: =(SUM(E14+E7)/2) -> 596.74 | F21: =(SUM(F14+F7)/2) -> 495.105 | G21: =(SUM(G14+G7)/2) -> 454.43
B22: 5.5 | C22: =(SUM(C15+C8)/2) -> 892.05 | D22: =(SUM(D15+D8)/2) -> 818.9875 | E22: =(SUM(E15+E8)/2) -> 745.925 | F22: =(SUM(F15+F8)/2) -> 618.88125 | G22: =(SUM(G15+G8)/2) -> 568.0375
B24: total amount of payment | C24: =C15*C11 -> 0 | D24: =D14*D11 -> 0 | E24: =E13*E11 -> 0 | F24: =F13*F11 -> 0 | G24: =G12*G11 -> 0
B25: total cost per year | C25: ='Total Costs'!B20 -> 0 | D25: ='Total Costs'!C20 -> 0 | E25: ='Total Costs'!D20 -> 0 | F25: ='Total Costs'!E20 -> 0 | G25: ='Total Costs'!F20 -> 0
B26: cost/payment ratio | C26: =C25/C24 -> #DIV/0! | D26: =D25/D24 -> #DIV/0! | E26: =E25/E24 -> #DIV/0! | F26: =F25/F24 -> #DIV/0! | G26: =G25/G24 -> #DIV/0!
B29: Lease Model
B30: Alternative Pricing Model (After USD/TR fuckup)
B31: Gross Margin | C31: 10 | D31: 50 | E31: 100 | F31: 500 | G31: 1000
B32: 4 | C32: =C5/16 -> 66.90375 | D32: =D5/16 -> 61.424063 | E32: =E5/16 -> 55.944375 | F32: =F5/16 -> 46.416094 | G32: =G5/16 -> 42.602812
B33: 4.5 | C33: =C6/16 -> 78.054375 | D33: =D6/16 -> 71.661406 | E33: =E6/16 -> 65.268438 | F33: =F6/16 -> 54.152109 | G33: =G6/16 -> 49.703281
B34: 5 | C34: =C7/16 -> 89.205 | D34: =D7/16 -> 81.89875 | E34: =E7/16 -> 74.5925 | F34: =F7/16 -> 61.888125 | G34: =G7/16 -> 56.80375
B35: 5.5 | C35: =C8/16 -> 111.50625 | D35: =D8/16 -> 102.37344 | E35: =E8/16 -> 93.240625 | F35: =F8/16 -> 77.360156 | G35: =G8/16 -> 71.004687

Sheet Live-currencies
A1: USD/TRY
A2: 20
